Workbook

Sheet READ ME & Method
A1: CODING EVIDENCE WORKBOOK
A2: Coding approach (per Mayring) | B2: ABDUCTIVE qualitative content analysis (Mayring, 2014): the six DIMENSIONS (D1-D6) were fixed deductively a priori from the theoretical framework (my thesis Chapter 2). Within each dimension, an initial set of MUTUALLY EXCLUSIVE CODES was derived deductively from named field taxonomies (see Codebook, 'Grounding' and 'Origin' columns). Where segments revealed content the deductive set could not cover, extension codes were added (marked 'Abductive extension'), starting with an initial scheme and extending it on new findings = abductive coding.
A3: What a CODE is | B3: A code is a mutually exclusive category inside one dimension. Each segment receives exactly ONE code per relevant dimension, chosen from that dimension's predefined set (dropdown). Dimensions the segment does not address are marked '-'.
A4: Unit of coding | B4: Segment / sentence level with page indication (not article level). Every code is attached to a verbatim quotation with its page reference and a written coding decision.
A5: Coverage (secondary attribute) | B5: Yes / Partial / No records HOW FULLY the source treats the dimension, per the operational criteria of my thesis Table 3.5. It is a separate, ordinal attribute alongside the categorical code, the code says WHAT the segment asserts; coverage says HOW COMPLETELY the dimension is addressed. Coverage feeds thesis Tables 4.2/4.3/4.4; codes feed the theme analysis.
A6: Themes | B6: Recurring code patterns roll up into the Governance Gap Taxonomy themes (AAG, CPCG, SRBG, CRPNG, FIAMG), in my thesis Table 4.5. See sheet 'Frequency & Themes'.
A7: Sheets in this workbook | B7: 1) Codebook: the code sets per dimension, with definitions, grounding taxonomy, origin (deductive/abductive), assignment rule, live segment counts. 2) Coding Form (Segments x Dimensions): the layout adapted from the video suggested by my supervisor (one row per unique segment, one dropdown-coded column per dimension. ("How to create a coding form and extract data for a systematic review or meta-analysis" : https://www.youtube.com/watch?v=BfB37q5DvAY) 3) Coding Book - Detail): one row per code assignment, with verbatim segment, page, coding decision, coverage. 4) Coverage Matrix: study-level Yes/Partial/No (= my thesis Table 4.2 context). 5) Frequency & Themes: live code counts and code-to-theme mapping. 6-7) PRISMA Search Log / Screening Log: identification, screening evidence
A8: Where the code definitions come from | B8: D1 <- NIST SP 800-145 deployment models, extended per Ali et al. (2025) and Yeboah-Ofori et al. (2024). D2 <- NIST CSF 2.0 GOVERN subcategories + ISO/IEC 27001 ISMS structure. D3 <- NIST CSF 2.0 function taxonomy applied to enforcement controls - PROTECT / DETECT / RESPOND-RECOVER (NIST, 2024) - plus access-control mechanisms per NIST SP 800-210 (Hu et al., 2020). D4 <- CSA v5 Shared Security Responsibility Model. D5 <- NIST CSF 2.0 operational functions (ID/PR/DE/RS-RC) + CSPM per CSA v5. D6 <- Cuzzocrea & Belmerabet (2024) seven-topic IAM taxonomy + CSA v5 Domain 5 IdP/RP terminology. -> All groundings are corpus sources, cited in the thesis.

Sheet Codebook
A1: CODEBOOK - mutually exclusive codes within each dimension
A2: # Segments = live count over 'Coding Book - Detail'. Zero-count codes are retained deliberately: they are part of the a-priori deductive sets.
A4: D1 | B4: Multi-Cloud Environment Focus | C4: Grounding: NIST SP 800-145 cloud deployment models (Mell & Grance, 2011 - thesis Ch. 2); multi-cloud split per Ali et al. (2025) multi/hybrid distinction and Yeboah-Ofori et al. (2024) operational labs
A5: Assignment rule (mutual exclusivity): | B5: Assign the most specific architecture the segment actually addresses: operational multi-cloud (D1.4) > conceptual multi-cloud (D1.3) > hybrid (D1.2) > single/agnostic (D1.1). Exactly one code per segment.
A6: Code | B6: Code name | C6: Definition (what a segment with this code asserts) | D6: Grounding / origin | E6: Origin type | F6: # Segments
A7: D1.1 | B7: Single-cloud / architecture-agnostic | C7: Segment treats one cloud only, or is written provider-agnostically with no cross-provider content. | D7: Deductive (SP 800-145) | E7: Deductive | F7: =COUNTIF('Coding Book - Detail'!C:C,A7) -> 7
A8: D1.2 | B8: Hybrid-cloud | C8: Segment addresses cloud + on-premises (hybrid) as the stated architecture. | D8: Deductive (SP 800-145) | E8: Deductive | F8: =COUNTIF('Coding Book - Detail'!C:C,A8) -> 0
A9: D1.3 | B9: Multi-cloud - conceptual / review scope | C9: Multi-cloud is the review/survey scope or is acknowledged conceptually, without operating 2+ providers. | D9: Abductive extension (Ali et al., 2025) | E9: Abductive | F9: =COUNTIF('Coding Book - Detail'!C:C,A9) -> 5
A10: D1.4 | B10: Multi-cloud - operational (2+ concurrent providers) | C10: Segment implements, benchmarks or evaluates 2+ concurrent public providers (e.g. Azure Arc + AWS EKS + GCP Anthos). | D10: Abductive extension (Yeboah-Ofori et al., 2024) | E10: Abductive | F10: =COUNTIF('Coding Book - Detail'!C:C,A10) -> 2
A12: D2 | B12: Cloud Governance | C12: Grounding: NIST CSF 2.0 GOVERN-function subcategories (NIST, 2024); ISMS clause structure per ISO/IEC 27001:2022
A13: Assignment rule (mutual exclusivity): | B13: If the segment names a specific governance instrument, use the matching GV code (D2.OC/RM/RR/PO/OV/SC). If it presents a whole management system / framework, use D2.FW. If governance is referenced or posed as a challenge without a structure, use D2.X. Exactly one code per segment.
A14: Code | B14: Code name | C14: Definition (what a segment with this code asserts) | D14: Grounding / origin | E14: Origin type | F14: # Segments
A15: D2.OC | B15: GV.OC Organizational Context | C15: Governance framed via organisational context/objectives. | D15: Deductive (NIST CSF GV.OC) | E15: Deductive | F15: =COUNTIF('Coding Book - Detail'!C:C,A15) -> 0
A16: D2.RM | B16: GV.RM Risk Mgmt Strategy | C16: Governance expressed as a risk-management strategy. | D16: Deductive (NIST CSF GV.RM) | E16: Deductive | F16: =COUNTIF('Coding Book - Detail'!C:C,A16) -> 0
A17: D2.RR | B17: GV.RR Roles, Responsibilities & Authorities | C17: Governance via defined roles/responsibilities/authorities. | D17: Deductive (NIST CSF GV.RR) | E17: Deductive | F17: =COUNTIF('Coding Book - Detail'!C:C,A17) -> 0
A18: D2.PO | B18: GV.PO Policy (policy instrument) | C18: Governance via a defined security policy instrument / policy structure. | D18: Deductive (NIST CSF GV.PO) | E18: Deductive | F18: =COUNTIF('Coding Book - Detail'!C:C,A18) -> 1
A19: D2.OV | B19: GV.OV Oversight | C19: Governance via oversight / continuous evaluation. | D19: Deductive (NIST CSF GV.OV) | E19: Deductive | F19: =COUNTIF('Coding Book - Detail'!C:C,A19) -> 0
A20: D2.SC | B20: GV.SC Supply-Chain / Provider Relationships | C20: Governance of provider/supply-chain relationships. | D20: Deductive (NIST CSF GV.SC) | E20: Deductive | F20: =COUNTIF('Coding Book - Detail'!C:C,A20) -> 0
A21: D2.FW | B21: Holistic / whole-framework governance (ISMS-level) | C21: A whole governance framework or management-system structure (ISO 27001 clauses; the entire GOVERN function; a complete ISG framework). | D21: Abductive extension (ISO/IEC 27001 ISMS) | E21: Abductive | F21: =COUNTIF('Coding Book - Detail'!C:C,A21) -> 7
A22: D2.X | B22: Governance referenced / challenge documented, no framework | C22: Governance mentioned, or named as a challenge, without any framework or instrument being defined. | D22: Abductive extension (this corpus) | E22: Abductive | F22: =COUNTIF('Coding Book - Detail'!C:C,A22) -> 4
A24: D3 | B24: Policy Enforcement | C24: Grounding: ISO/IEC 27001:2022 Annex A control-type attribute - preventive / detective / corrective (ISO/IEC, 2022); access-control mechanisms per NIST SP 800-210 (Hu et al., 2020)
A25: Assignment rule (mutual exclusivity): | B25: If a concrete enforcement mechanism is named, code its control type per the ISO/IEC 27001:2022 Annex A attribute (D3.1 preventive / D3.2 detective / D3.3 corrective - choose the dominant type). If policy is only specified or its need argued, use D3.4. Exactly one code per segment.
A26: Code | B26: Code name | C26: Definition (what a segment with this code asserts) | D26: Grounding / origin | E26: Origin type | F26: # Segments
A27: D3.1 | B27: Preventive control - access control, encryption, ABAC/RBAC | C27: A preventive enforcement control is named: access control, encryption, RBAC/ABAC, configuration control (Annex A control-type: preventive). | D27: Deductive (ISO 27001 Annex A) | E27: Deductive | F27: =COUNTIF('Coding Book - Detail'!C:C,A27) -> 4
A28: D3.2 | B28: Detective control - monitoring, logging, audit | C28: A detective enforcement control is named: monitoring, logging, intrusion detection, audit (Annex A control-type: detective). | D28: Deductive (ISO 27001 Annex A) | E28: Deductive | F28: =COUNTIF('Coding Book - Detail'!C:C,A28) -> 0
A29: D3.3 | B29: Corrective control - remediation, response | C29: A corrective enforcement control is named: remediation or incident response (Annex A control-type: corrective). | D29: Deductive (ISO 27001 Annex A) | E29: Deductive | F29: =COUNTIF('Coding Book - Detail'!C:C,A29) -> 0
A30: D3.4 | B30: Policy specification only (no enforcement mechanism) | C30: Policy is stated, required, or its challenge argued, but no concrete enforcement mechanism is defined. | D30: Abductive extension (this corpus) | E30: Abductive | F30: =COUNTIF('Coding Book - Detail'!C:C,A30) -> 7
A32: D4 | B32: Shared Responsibility | C32: Grounding: CSA Security Guidance v5 Shared Security Responsibility Model - SSRM (CSA, 2021); NSA shared-responsibility guidance (2024)
A33: Assignment rule (mutual exclusivity): | B33: Code by the allocation the segment makes: provider (D4.1), customer (D4.2), or jointly defined split (D4.3). If responsibility is referenced without allocating a boundary, use D4.4. Exactly one code per segment.
A34: Code | B34: Code name | C34: Definition (what a segment with this code asserts) | D34: Grounding / origin | E34: Origin type | F34: # Segments
A35: D4.1 | B35: Provider-managed | C35: Control/obligation allocated to the provider. | D35: Deductive (SSRM) | E35: Deductive | F35: =COUNTIF('Coding Book - Detail'!C:C,A35) -> 0
A36: D4.2 | B36: Customer-managed | C36: Control/obligation allocated to the customer. | D36: Deductive (SSRM) | E36: Deductive | F36: =COUNTIF('Coding Book - Detail'!C:C,A36) -> 0
A37: D4.3 | B37: Shared / jointly-managed (SSRM across IaaS/PaaS/SaaS) | C37: Responsibility split defined across provider and customer (per service model). | D37: Deductive (SSRM) | E37: Deductive | F37: =COUNTIF('Coding Book - Detail'!C:C,A37) -> 4
A38: D4.4 | B38: Boundary referenced, not allocated | C38: Shared responsibility mentioned, but no boundary actually allocated. | D38: Abductive extension (this corpus) | E38: Abductive | F38: =COUNTIF('Coding Book - Detail'!C:C,A38) -> 3
A40: D5 | B40: Risk Posture Management | C40: Grounding: NIST CSF 2.0 operational functions ID / PR / DE / RS-RC (NIST, 2024); CSPM per CSA Security Guidance v5 Domain 6
A41: Assignment rule (mutual exclusivity): | B41: Code the CSF function of the posture activity the segment describes (D5.ID / D5.PR / D5.DE / D5.RS). If risk is referenced without a posture mechanism, use D5.X. Exactly one code per segment.
A42: Code | B42: Code name | C42: Definition (what a segment with this code asserts) | D42: Grounding / origin | E42: Origin type | F42: # Segments
A43: D5.ID | B43: ID - Risk identification / assessment | C43: Risk identification or assessment activity (incl. quantitative evaluation). | D43: Deductive (NIST CSF ID) | E43: Deductive | F43: =COUNTIF('Coding Book - Detail'!C:C,A43) -> 4
A44: D5.PR | B44: PR - Protective safeguards | C44: Protective safeguards for posture. | D44: Deductive (NIST CSF PR) | E44: Deductive | F44: =COUNTIF('Coding Book - Detail'!C:C,A44) -> 0
A45: D5.DE | B45: DE - Continuous monitoring / detection (CSPM) | C45: Continuous monitoring / detection, incl. CSPM tooling. | D45: Deductive (NIST CSF DE) | E45: Deductive | F45: =COUNTIF('Coding Book - Detail'!C:C,A45) -> 6
...

Sheet Coding Form (Seg x Dim)
A1: Note: One row per unique segment. Each dimension column holds exactly one code from that dimension's mutually exclusive set; 'n/a' = source does not substantively address the dimension (coverage No) - the source simply never talks about that dimension,; '-' = this segment was not the evidence unit for that dimension. Coding decisions per code: sheet 'Coding Book - Detail'.
A3: Seg | B3: Source | C3: Layer | D3: Page | E3: Segment (verbatim, from original text) | F3: D1 | G3: D2 | H3: D3 | I3: D4 | J3: D5 | K3: D6
A4: 1 | B4: AlGhamdi et al. (2020) | C4: L3 | D4: 1 | E4: paper addresses "information security governance" as a general organisational domain; no multi-cloud or cross-provider context addressed (p.1; abstract). | F4: D1.1 | G4: - | H4: - | I4: - | J4: - | K4: -
A5: 2 | B5: Ali et al. (2025) | C5: L3 | D5: 1 | E5: "This review comprehensively examines the critical security and privacy concerns associated with multi-cloud and hybrid cloud architectures" (abstract, p.1). | F5: D1.3 | G5: - | H5: - | I5: - | J5: - | K5: -
A6: 3 | B6: Aljarrah et al. (2024) | C6: L3 | D6: 136 | E6: paper provides "a comprehensive analysis of the current state of the art in cybersecurity risk assessment, governance, and compliance" across 24 models (p.136); no multi-cloud or cross-provider architecture addressed. | F6: D1.1 | G6: - | H6: - | I6: - | J6: - | K6: -
A7: 4 | B7: Alouffi et al. (2021) | C7: L3 | D7: 57792 | E7: "in this SLR, we have reviewed the literature on cloud computing topics, including cloud security threats and their mitigation strategies."; "examined the research studies published between 2010 and 2020" (p.57792); | F7: D1.3 | G7: n/a | H7: - | I7: n/a | J7: - | K7: n/a
A8: 5 | B8: CSA Security Guidance v5 (2021) | C8: L1 | D8: 98 | E8: "While this is our recommendation, we also understand that many CSCs are forced to support multi-cloud before reaching the expected maturity level" (CSA, 2021, p.98); multi-cloud acknowledged conceptually in Domains 3-4 as advisory guidance. | F8: D1.3 | G8: - | H8: - | I8: - | J8: - | K8: -
A9: 6 | B9: Cuzzocrea & Belmerabet (2024) | C9: L3 | D9: 6224 | E9: Organized around seven core topics, Authentication and Authorization, Identity Verification and Risk Management, Attribute Management, Security and Privacy, Audit and Compliance, User Lifecycle Management, and Interoperability and Federation, this study provides "this study provides a detailed examination of these aspects particularly to achieve robust security, privacy, and interoperability across multi- loud platforms." organised around seven core IAM topics (p.6224). | F9: D1.3 | G9: - | H9: n/a | I9: - | J9: - | K9: D6.IF
A10: 7 | B10: Diningrat et al. (2025) | C10: L3 | D10: 70006 | E10: "This study uses a systematic literature review methodology adopting the Kitchenham method, which includes a literature search across leading academic databases including IEEE Xplore, ScienceDirect, ACM, SpringerLink, Emerald Insight, Nature, Taylor & Francis, Scopus, and ProQuest. A formal protocol was followed to conduct an automated search of relevant articles published between 2021 and 2024, and filters were applied. Based on the initial search results, 2038 studies were found, then the selection criteria process (inclusion and exclusion) and quality assessment were carried out, and finally 30 studies were selected for further research." (p.70006). | F10: D1.3 | G10: - | H10: - | I10: - | J10: - | K10: -
A11: 8 | B11: Hegde et al. (2023) | C11: L3 | D11: 1 | E11: paper evaluates "ISO/IEC 27001 and 27002, FedRAMP, and SOC 2 against a third-party benchmark, the Cloud Controls Matrix" (p.1); no multi-cloud or cross-provider architecture addressed. | F11: D1.1 | G11: - | H11: - | I11: - | J11: - | K11: -
A12: 9 | B12: ISO/IEC 27001:2022 | C12: L1 | D12: 12 | E12: standard is architecture-agnostic; A.5.23 addresses "Information security for use of cloud services" but does not distinguish between single-provider and multi-provider architecture (Annex A, p.12). | F12: D1.1 | G12: - | H12: - | I12: - | J12: - | K12: -
A13: 10 | B13: Kaur et al. (2024) | C13: L2 | D13: 2 | E13: paper proposes "The Multi-Cloud Security Model brings inter-server verbal exchange, authentication integrity"; study "The primary goal of this investigation is to create a safe architecture for inter-server communication within multi-cloud systems". (Introduction) | F13: D1.4 | G13: - | H13: - | I13: - | J13: - | K13: -
A14: 11 | B14: NIST CSF 2.0 (2024) | C14: L1 | D14: 2 | E14: "The CSF is designed to be used by organizations of all sizes and sectors, including industry, government, academia, and nonprofit organizations, regardless of the maturity level of their cybersecurity programs." (NIST, 2024, p.2); GV.SC addresses supply chain and cloud provider relationships generically, "GV.SC-01: A cybersecurity supply chain risk management program, strategy, objectives, policies, and processes are established and agreed to by organizational stakeholders" (NIST, 2024, p.17), without distinguishing single-provider from multi-provider governance requirements. | F14: D1.1 | G14: - | H14: - | I14: - | J14: - | K14: -
A15: 12 | B15: NIST SP 800-210 (Hu et al., 2020) | C15: L1 | D15: abstract | E15: "This document presents cloud access control (AC) characteristics and a set of general access control guidance for cloud service models-IaaS (Infrastructure as a Service), PaaS (Platform as a Service), and SaaS (Software as a Service)" (p. iv). | F15: D1.1 | G15: - | H15: - | I15: - | J15: - | K15: -
A16: 13 | B16: Pöhn & Hillmann (2021) | C16: L3 | D16: 196 | E16: paper presents a "Reference Service Model for Federated Identity Management" - provider-heterogeneous deployment not stated; model is architecturally provider-agnostic (p.196). | F16: D1.1 | G16: - | H16: n/a | I16: - | J16: - | K16: -
A17: 14 | B17: Yeboah-Ofori et al. (2024) | C17: L2 | D17: 218 | E17: "we used the Kill Chain attack model for our implementation to determine the tactics, techniques, and procedures (TTP) used by cyberattacks to exploit the multi-cloud environment" (p. 218). | F17: D1.4 | G17: - | H17: - | I17: - | J17: - | K17: -
A18: 15 | B18: AlGhamdi et al. (2020) | C18: L3 | D18: 28 | E18: "the review identified the need for developing a holistic framework for the information security governance that (1) connects the organization's objectives and its protection, (2) addresses each aspect of strategy, control, and regulation, (3) ensures compliance of procedures and guidelines with policies, and (4) ensures continuous evaluation and compliance" (p.28). | F18: - | G18: D2.FW | H18: - | I18: - | J18: - | K18: -
A19: 16 | B19: Ali et al. (2025) | C19: L3 | D19: 1 | E19: paper provides "We analyze existing security strategies, including cryptographic techniques, identity and access management (IAM) mechanisms, AI-driven threat detection, and privacy-preserving methodologies. Furthermore, we provide a comparative evaluation of these approaches, highlighting their trade-offs in terms of security effectiveness, computational overhead, and deployment feasibility". it is covering IAM, data security, network security, regulatory compliance (abstract, p.1). | F19: - | G19: D2.FW | H19: - | I19: - | J19: - | K19: -
A20: 17 | B20: Aljarrah et al. (2024) | C20: L3 | D20: 139 | E20: "The evaluation framework (shown in Figure 1) is based on nine essential metrics that collectively provide a comprehensive assessment of cybersecurity risk assessment, governance, and compliance models. Privacy measurement... performance... precision... ethics... customisation... integration capabilities... resilience... automation levels... cost evaluations" (p.139). | F20: - | G20: D2.FW | H20: - | I20: - | J20: - | K20: -
A21: 18 | B21: CSA Security Guidance v5 (2021) | C21: L1 | D21: 28 | E21: Domain 2 provides "cloud governance" covering policies, procedures, roles, and compliance, and the relationship between CSP and CSC (CSA, 2021, p.28). | F21: - | G21: D2.FW | H21: - | I21: - | J21: - | K21: -
A22: 19 | B22: Cuzzocrea & Belmerabet (2024) | C22: L3 | D22: 6224 | E22: "Federated identity management solutions, on the other hand, have the ability to offer permission and authentication across systems" - governance requirements for federation identified as requiring cross-provider establishment but no governance framework structure defined (p.6224). | F22: - | G22: D2.X | H22: - | I22: - | J22: - | K22: -
A23: 20 | B23: Diningrat et al. (2025) | C23: L3 | D23: 70006 | E23: "The security challenges in multi-cloud environments arise from the variability of security policies and standards among providers, resulting in configuration inconsistencies, complex authorization processes, and heightened risks of security breaches" (p.70006). | F23: - | G23: D2.X | H23: - | I23: D4.4 | J23: - | K23: -
A24: 21 | B24: Hegde et al. (2023) | C24: L3 | D24: 5 | E24: "FedRAMP Rev. 5, provided the highest alignment in coverage to CCM v4, with 94% of controls found in CCM having full coverage. ISO/IEC 27001/02:2022 provided the second highest alignment in coverage to CCM v4, with 61% of controls fully covered. SOC 2 had the lowest number of controls with full coverage, with only 28%" (p.5). | F24: - | G24: D2.FW | H24: - | I24: - | J24: - | K24: -
A25: 22 | B25: ISO/IEC 27001:2022 | C25: L1 | D25: 1-10 | E25: ISMS structure "Clauses 4 (Context of the organization), 5 (leadership), 6 (planning), 7 (support), 8 (operation), 9 (performance evaluation), 10 (improvement)" provide a complete auditable governance management system (Clauses 4-10, pp.1-10). | F25: - | G25: D2.FW | H25: - | I25: - | J25: - | K25: -
A26: 23 | B26: Kaur et al. (2024) | C26: L2 | D26: 2 | E26: "The primary goal of this investigation is to create a safe architecture for inter-server communication within multi-cloud systems" (Introduction); paper proposes and benchmarks SIDH, Blowfish, RSA, and BLAKE2 cryptographic algorithms for authentication performance - "overall execution time is 94.5 in SSCA and 55 in SIDH" (Results). | F26: - | G26: n/a | H26: n/a | I26: n/a | J26: - | K26: -
A27: 24 | B27: NIST CSF 2.0 (2024) | C27: L1 | D27: 16 | E27: GOVERN function defines subcategories "GV.OC (organisational context), GV.RM (risk management strategy), GV.RR (Roles, Responsibilities, and Authorities), GV.PO (policy), GV.OV (oversight), GV.SC (Cybersecurity Supply Chain Risk Management)" (NIST, 2024, p.16). | F27: - | G27: D2.FW | H27: - | I27: - | J27: - | K27: -
A28: 25 | B28: NIST SP 800-210 (Hu et al., 2020) | C28: L1 | D28: 7 | E28: "guidance for AC system for each cloud service model, as described in Sections 3, 4, and 6 of this document, can be further extended to system requirements by referring to the AC control elements listed in NIST SP 800-53" (p. 7). | F28: - | G28: D2.PO | H28: - | I28: - | J28: - | K28: -
A29: 26 | B29: Pöhn & Hillmann (2021) | C29: L3 | D29: 200 | E29: "the need for a holistic architecture view is mandatory to avoid duplication in realization and to obtain synergy effects between the different systems. Especially the collaboration of several institutions in a federation becomes a challenge due to the growing IT complexity and architecture as a whole" (p. 200). | F29: - | G29: D2.X | H29: - | I29: - | J29: - | K29: -
A30: 27 | B30: Yeboah-Ofori et al. (2024) | C30: L2 | D30: 220 | E30: "the key challenge and complexities associated with managing multi-cloud environments, particularly regarding governance, security, resource fragmentation, and compliance, is establishing effective governance practices" (p. 220). | F30: - | G30: D2.X | H30: - | I30: - | J30: - | K30: -
A31: 28 | B31: AlGhamdi et al. (2020) | C31: L3 | D31: 1 | E31: framework "ensures compliance of procedures and guidelines with policies" as one of its four structural components (abstract, p.1). | F31: - | G31: - | H31: D3.4 | I31: - | J31: - | K31: -
A32: 29 | B32: Ali et al. (2025) | C32: L3 | D32: 11 | E32: "Identity management across several cloud providers demands IAM systems that deliver uniform identity services between multiple providers who maintain separate authentication protocols and authorization policies" (p.11). | F32: - | G32: - | H32: D3.4 | I32: - | J32: - | K32: D6.IF
A33: 30 | B33: Aljarrah et al. (2024) | C33: L3 | D33: 139 | E33: compliance scope assessed across frameworks - "Expanding compliance scope to create unified frameworks that help organizations efficiently navigate the complex web of security regulations is another key priority" (p.139). | F33: - | G33: - | H33: D3.4 | I33: - | J33: - | K33: -
A34: 31 | B34: Alouffi et al. (2021) | C34: L3 | D34: 57799 | E34: "Firewall configuration, server patching, and placement of the intrusion-detection system are enforced. The use of encryption and authentication processes can ensure data availability and con_x001C_dentiality" (p. 57799). | F34: - | G34: - | H34: D3.1 | I34: - | J34: - | K34: -
A35: 32 | B35: CSA Security Guidance v5 (2021) | C35: L1 | D35: 28 | E35: Domain 2 (CSA, 2021, p.28) and Domain 5 (CSA, 2021, p.103) address policy governance and IAM policy enforcement in cloud contexts. | F35: - | G35: - | H35: D3.4 | I35: - | J35: - | K35: -
A36: 33 | B36: Diningrat et al. (2025) | C36: L3 | D36: 70006 | E36: "most of the multi-cloud security issue trends fall into the areas of data, cryptography, authentication and authorization" (p.70006); "authentication and authorization" identified as dominant challenge category across reviewed papers (p.70012). | F36: - | G36: - | H36: D3.4 | I36: - | J36: - | K36: -
A37: 34 | B37: Hegde et al. (2023) | C37: L3 | D37: 4-5 | E37: policy enforcement coverage inferred from overall CCM control coverage percentages (p.4-5); "CCM v4 encapsulates a holistic approach to risk management" (p.5) but Hegde does not isolate policy enforcement as an independent result. | F37: - | G37: - | H37: D3.4 | I37: - | J37: - | K37: -
A38: 35 | B38: ISO/IEC 27001:2022 | C38: L1 | D38: 12 | E38: Annex A control "A.5.23 Information security for use of cloud services" (p.12); "A.8.9 configuration management" (p. 16); Clause "5.2 policy (p.3). | F38: - | G38: - | H38: D3.1 | I38: - | J38: - | K38: -
... A60: 57 | B60: ISO/IEC 27001:2022 | C60: L1 | D60: 3 | E60: Clause "6.1 Actions to address risks and opportunities" mandates risk identification, analysis, and evaluation as part of ISMS planning (p.3). | F60: - | G60: - | H60: - | I60: - | J60: D5.DE | K60: -
A61: 58 | B61: Kaur et al. (2024) | C61: L2 | D61: 9 | E61: "The achieved response time is 3.85 in SSCA and 2.01 in SIDH" - benchmark comparing proposed SIDH authentication against SSCA (Scalable and Secure Cloud Architecture) in simulated multi-cloud environment; "overall execution time is 94.5 in SSCA and 55 in SIDH" (Table 5 results section). | F61: - | G61: - | H61: - | I61: - | J61: D5.ID | K61: -
A62: 59 | B62: NIST CSF 2.0 (2024) | C62: L1 | D62: 21 | E62: "Continuous Monitoring (DE.CM)" DE.CM-01 through DE.CM-09 continuous monitoring subcategories (NIST, 2024, p.21); "Risk Assessment (ID.RA)" ID.RA-01 through ID.RA-10 risk assessment subcategories (NIST, 2024, p.18). | F62: - | G62: - | H62: - | I62: - | J62: D5.DE | K62: -
...

Sheet Coding Book - Detail
A1: the code says what kind of thing a sentence asserts; coverage says how completely the source handles the topic.
A2: Seg | B2: Dimension | C2: Code | D2: Source | E2: Segment (verbatim) | F2: Page | G2: Coding decision (why this code) | H2: Coverage (Table 3.5)
A3: 1 | B3: D1 - Multi-Cloud Environment Focus | C3: D1.1 | D3: AlGhamdi et al. (2020) | E3: paper addresses "information security governance" as a general organisational domain; no multi-cloud or cross-provider context addressed (p.1; abstract). | F3: 1 | G3: No multi-cloud or cross-provider architecture content → No. | H3: No
A4: 2 | B4: D1 - Multi-Cloud Environment Focus | C4: D1.3 | D4: Ali et al. (2025) | E4: "This review comprehensively examines the critical security and privacy concerns associated with multi-cloud and hybrid cloud architectures" (abstract, p.1). | F4: 1 | G4: Explicitly multi-cloud and hybrid-cloud framed → Yes. | H4: Yes
A5: 3 | B5: D1 - Multi-Cloud Environment Focus | C5: D1.1 | D5: Aljarrah et al. (2024) | E5: paper provides "a comprehensive analysis of the current state of the art in cybersecurity risk assessment, governance, and compliance" across 24 models (p.136); no multi-cloud or cross-provider architecture addressed. | F5: 136 | G5: General cybersecurity governance scope; no multi-cloud framing → No. | H5: No
A6: 4 | B6: D1 - Multi-Cloud Environment Focus | C6: D1.3 | D6: Alouffi et al. (2021) | E6: "in this SLR, we have reviewed the literature on cloud computing topics, including cloud security threats and their mitigation strategies."; "examined the research studies published between 2010 and 2020" (p.57792); | F6: 57792 | G6: Cloud environments addressed broadly; multi-cloud not the explicit frame but cross-provider threats included → Partial. | H6: Partial
A7: 5 | B7: D1 - Multi-Cloud Environment Focus | C7: D1.3 | D7: CSA Security Guidance v5 (2021) | E7: "While this is our recommendation, we also understand that many CSCs are forced to support multi-cloud before reaching the expected maturity level" (CSA, 2021, p.98); multi-cloud acknowledged conceptually in Domains 3-4 as advisory guidance. | F7: 98 | G7: Multi-cloud acknowledged conceptually but no prescriptive cross-provider governance requirements defined → Partial. | H7: Partial*
A8: 6 | B8: D1 - Multi-Cloud Environment Focus | C8: D1.3 | D8: Cuzzocrea & Belmerabet (2024) | E8: Organized around seven core topics, Authentication and Authorization, Identity Verification and Risk Management, Attribute Management, Security and Privacy, Audit and Compliance, User Lifecycle Management, and Interoperability and Federation, this study provides "this study provides a detailed examination of these aspects particularly to achieve robust security, privacy, and interoperability across multi- loud platforms." organised around seven core IAM topics (p.6224). | F8: 6224 | G8: Multi-cloud IAM explicitly the stated focus and context of the survey → Yes. | H8: Yes
A9: 7 | B9: D1 - Multi-Cloud Environment Focus | C9: D1.3 | D9: Diningrat et al. (2025) | E9: "This study uses a systematic literature review methodology adopting the Kitchenham method, which includes a literature search across leading academic databases including IEEE Xplore, ScienceDirect, ACM, SpringerLink, Emerald Insight, Nature, Taylor & Francis, Scopus, and ProQuest. A formal protocol was followed to conduct an automated search of relevant articles published between 2021 and 2024, and filters were applied. Based on the initial search results, 2038 studies were found, then the selection criteria process (inclusion and exclusion) and quality assessment were carried out, and finally 30 studies were selected for further research." (p.70006). | F9: 70006 | G9: Explicitly multi-cloud scoped systematic review → Yes. | H9: Yes
A10: 8 | B10: D1 - Multi-Cloud Environment Focus | C10: D1.1 | D10: Hegde et al. (2023) | E10: paper evaluates "ISO/IEC 27001 and 27002, FedRAMP, and SOC 2 against a third-party benchmark, the Cloud Controls Matrix" (p.1); no multi-cloud or cross-provider architecture addressed. | F10: 1 | G10: Single-cloud coverage mapping only; no multi-cloud framing → No. | H10: No
A11: 9 | B11: D1 - Multi-Cloud Environment Focus | C11: D1.1 | D11: ISO/IEC 27001:2022 | E11: standard is architecture-agnostic; A.5.23 addresses "Information security for use of cloud services" but does not distinguish between single-provider and multi-provider architecture (Annex A, p.12). | F11: 12 | G11: No multi-cloud or cross-provider specificity → No. | H11: No
A12: 10 | B12: D1 - Multi-Cloud Environment Focus | C12: D1.4 | D12: Kaur et al. (2024) | E12: paper proposes "The Multi-Cloud Security Model brings inter-server verbal exchange, authentication integrity"; study "The primary goal of this investigation is to create a safe architecture for inter-server communication within multi-cloud systems". (Introduction) | F12: 2 | G12: Multi-cloud environment is the explicit experimental context → Yes. | H12: Yes
A13: 11 | B13: D1 - Multi-Cloud Environment Focus | C13: D1.1 | D13: NIST CSF 2.0 (2024) | E13: "The CSF is designed to be used by organizations of all sizes and sectors, including industry, government, academia, and nonprofit organizations, regardless of the maturity level of their cybersecurity programs." (NIST, 2024, p.2); GV.SC addresses supply chain and cloud provider relationships generically, "GV.SC-01: A cybersecurity supply chain risk management program, strategy, objectives, policies, and processes are established and agreed to by organizational stakeholders" (NIST, 2024, p.17), without distinguishing single-provider from multi-provider governance requirements. | F13: 2 | G13: Framework is architecture-agnostic by explicit design; no subcategory specifies governance requirements for concurrent multi-provider deployment → No. | H13: No
A14: 12 | B14: D1 - Multi-Cloud Environment Focus | C14: D1.1 | D14: NIST SP 800-210 (Hu et al., 2020) | E14: "This document presents cloud access control (AC) characteristics and a set of general access control guidance for cloud service models-IaaS (Infrastructure as a Service), PaaS (Platform as a Service), and SaaS (Software as a Service)" (p. iv). | F14: abstract | G14: Single cloud service model scope only; no multi-cloud or cross-provider context; D1 = No. | H14: No
A15: 13 | B15: D1 - Multi-Cloud Environment Focus | C15: D1.1 | D15: Pöhn & Hillmann (2021) | E15: paper presents a "Reference Service Model for Federated Identity Management" - provider-heterogeneous deployment not stated; model is architecturally provider-agnostic (p.196). | F15: 196 | G15: No multi-cloud architecture context; federation model is provider-agnostic in design → No. | H15: No
A16: 14 | B16: D1 - Multi-Cloud Environment Focus | C16: D1.4 | D16: Yeboah-Ofori et al. (2024) | E16: "we used the Kill Chain attack model for our implementation to determine the tactics, techniques, and procedures (TTP) used by cyberattacks to exploit the multi-cloud environment" (p. 218). | F16: 218 | G16: Explicitly multi-cloud lab (Azure Arc, AWS EKS, GCP Anthos); D1 = Yes - empirical multi-cloud focus confirmed. | H16: Yes
A17: 15 | B17: D2 - Cloud Governance | C17: D2.FW | D17: AlGhamdi et al. (2020) | E17: "the review identified the need for developing a holistic framework for the information security governance that (1) connects the organization's objectives and its protection, (2) addresses each aspect of strategy, control, and regulation, (3) ensures compliance of procedures and guidelines with policies, and (4) ensures continuous evaluation and compliance" (p.28). | F17: 28 | G17: Explicit, complete information security governance framework with four defined structural components → Yes. | H17: Yes
A18: 16 | B18: D2 - Cloud Governance | C18: D2.FW | D18: Ali et al. (2025) | E18: paper provides "We analyze existing security strategies, including cryptographic techniques, identity and access management (IAM) mechanisms, AI-driven threat detection, and privacy-preserving methodologies. Furthermore, we provide a comparative evaluation of these approaches, highlighting their trade-offs in terms of security effectiveness, computational overhead, and deployment feasibility". it is covering IAM, data security, network security, regulatory compliance (abstract, p.1). | F18: 1 | G18: Broad governance analysis with comparative structure across multiple security domains → Yes. | H18: Yes
A19: 17 | B19: D2 - Cloud Governance | C19: D2.FW | D19: Aljarrah et al. (2024) | E19: "The evaluation framework (shown in Figure 1) is based on nine essential metrics that collectively provide a comprehensive assessment of cybersecurity risk assessment, governance, and compliance models. Privacy measurement... performance... precision... ethics... customisation... integration capabilities... resilience... automation levels... cost evaluations" (p.139). | F19: 139 | G19: Comprehensive structured governance evaluation across 24 models and 9 metrics → Yes. | H19: Yes
A20: 18 | B20: D2 - Cloud Governance | C20: n/a (gap) | D20: Alouffi et al. (2021) | E20: "in this SLR, we have reviewed the literature on cloud computing topics, including cloud security threats and their mitigation strategies" (p.57805); paper produces a three-level threat taxonomy (Fig. 6, p.57802) classifying threats without defining governance frameworks, oversight mechanisms, or accountability structures. | F20: 57805 | G20: Paper scope is threat identification and mitigation classification; no governance framework or structure content → No. | H20: No
A21: 19 | B21: D2 - Cloud Governance | C21: D2.FW | D21: CSA Security Guidance v5 (2021) | E21: Domain 2 provides "cloud governance" covering policies, procedures, roles, and compliance, and the relationship between CSP and CSC (CSA, 2021, p.28). | F21: 28 | G21: Cloud governance explicitly addressed as a domain; D2 → Yes | H21: Yes
A22: 20 | B22: D2 - Cloud Governance | C22: D2.X | D22: Cuzzocrea & Belmerabet (2024) | E22: "Federated identity management solutions, on the other hand, have the ability to offer permission and authentication across systems" - governance requirements for federation identified as requiring cross-provider establishment but no governance framework structure defined (p.6224). | F22: 6224 | G22: Governance referenced conceptually in the federation context; no complete governance framework or structure provided → Partial. | H22: Partial
A23: 21 | B23: D2 - Cloud Governance | C23: D2.X | D23: Diningrat et al. (2025) | E23: "The security challenges in multi-cloud environments arise from the variability of security policies and standards among providers, resulting in configuration inconsistencies, complex authorization processes, and heightened risks of security breaches" (p.70006). | F23: 70006 | G23: Governance challenges documented thematically; no governance framework or structure defined → Partial. | H23: Partial
A24: 22 | B24: D2 - Cloud Governance | C24: D2.FW | D24: Hegde et al. (2023) | E24: "FedRAMP Rev. 5, provided the highest alignment in coverage to CCM v4, with 94% of controls found in CCM having full coverage. ISO/IEC 27001/02:2022 provided the second highest alignment in coverage to CCM v4, with 61% of controls fully covered. SOC 2 had the lowest number of controls with full coverage, with only 28%" (p.5). | F24: 5 | G24: Structured quantitative governance coverage evaluation across three frameworks → Yes. | H24: Yes
A25: 23 | B25: D2 - Cloud Governance | C25: D2.FW | D25: ISO/IEC 27001:2022 | E25: ISMS structure "Clauses 4 (Context of the organization), 5 (leadership), 6 (planning), 7 (support), 8 (operation), 9 (performance evaluation), 10 (improvement)" provide a complete auditable governance management system (Clauses 4-10, pp.1-10). | F25: 1-10 | G25: Full, auditable governance management system structure with defined clauses → Yes. | H25: Yes
A26: 24 | B26: D2 - Cloud Governance | C26: n/a (gap) | D26: Kaur et al. (2024) | E26: "The primary goal of this investigation is to create a safe architecture for inter-server communication within multi-cloud systems" (Introduction); paper proposes and benchmarks SIDH, Blowfish, RSA, and BLAKE2 cryptographic algorithms for authentication performance - "overall execution time is 94.5 in SSCA and 55 in SIDH" (Results). | F26: 2 | G26: Paper scope is confined to cryptographic authentication benchmarking; no governance framework, policy structure, role definition, or oversight mechanism is defined anywhere in the paper → No. | H26: No
A27: 25 | B27: D2 - Cloud Governance | C27: D2.FW | D27: NIST CSF 2.0 (2024) | E27: GOVERN function defines subcategories "GV.OC (organisational context), GV.RM (risk management strategy), GV.RR (Roles, Responsibilities, and Authorities), GV.PO (policy), GV.OV (oversight), GV.SC (Cybersecurity Supply Chain Risk Management)" (NIST, 2024, p.16). | F27: 16 | G27: Dedicated governance function with defined subcategories covering full governance management scope → Yes. | H27: Yes
A28: 26 | B28: D2 - Cloud Governance | C28: D2.PO | D28: NIST SP 800-210 (Hu et al., 2020) | E28: "guidance for AC system for each cloud service model, as described in Sections 3, 4, and 6 of this document, can be further extended to system requirements by referring to the AC control elements listed in NIST SP 800-53" (p. 7). | F28: 7 | G28: Governance addressed as access control policy structure for individual service models; not a complete multi-cloud governance framework; D2 = Partial. | H28: Partial
A29: 27 | B29: D2 - Cloud Governance | C29: D2.X | D29: Pöhn & Hillmann (2021) | E29: "the need for a holistic architecture view is mandatory to avoid duplication in realization and to obtain synergy effects between the different systems. Especially the collaboration of several institutions in a federation becomes a challenge due to the growing IT complexity and architecture as a whole" (p. 200). | F29: 200 | G29: Governance referenced at the conceptual architectural level for federated identity management; no complete cloud governance framework structure defined; D2 = Partial. | H29: Partial
A30: 28 | B30: D2 - Cloud Governance | C30: D2.X | D30: Yeboah-Ofori et al. (2024) | E30: "the key challenge and complexities associated with managing multi-cloud environments, particularly regarding governance, security, resource fragmentation, and compliance, is establishing effective governance practices" (p. 220). | F30: 220 | G30: Governance named as the primary challenge category; D2 = Yes. | H30: Yes
A31: 29 | B31: D3 - Policy Enforcement | C31: D3.4 | D31: AlGhamdi et al. (2020) | E31: framework "ensures compliance of procedures and guidelines with policies" as one of its four structural components (abstract, p.1). | F31: 1 | G31: Policy compliance addressed as a governance element; no cloud-specific enforcement mechanism defined → Partial. | H31: Partial
A32: 30 | B32: D3 - Policy Enforcement | C32: D3.4 | D32: Ali et al. (2025) | E32: "Identity management across several cloud providers demands IAM systems that deliver uniform identity services between multiple providers who maintain separate authentication protocols and authorization policies" (p.11). | F32: 11 | G32: Policy enforcement requirements identified at cross-provider level; no prescriptive enforcement mechanism defined → Partial. | H32: Partial
A33: 31 | B33: D3 - Policy Enforcement | C33: D3.4 | D33: Aljarrah et al. (2024) | E33: compliance scope assessed across frameworks - "Expanding compliance scope to create unified frameworks that help organizations efficiently navigate the complex web of security regulations is another key priority" (p.139). | F33: 139 | G33: Policy governance addressed as evaluation dimension; no specific policy enforcement mechanism defined → Partial. | H33: Partial
A34: 32 | B34: D3 - Policy Enforcement | C34: D3.1 | D34: Alouffi et al. (2021) | E34: "Firewall configuration, server patching, and placement of the intrusion-detection system are enforced. The use of encryption and authentication processes can ensure data availability and con_x001C_dentiality" (p. 57799). | F34: 57799 | G34: Access control and authentication identified as security threat categories; policy enforcement addressed indirectly through threat identification; no enforcement mechanism defined → D3 = Partial. | H34: Partial
A35: 33 | B35: D3 - Policy Enforcement | C35: D3.4 | D35: CSA Security Guidance v5 (2021) | E35: Domain 2 (CSA, 2021, p.28) and Domain 5 (CSA, 2021, p.103) address policy governance and IAM policy enforcement in cloud contexts. | F35: 28 | G35: Policy enforcement addressed through dedicated domain-level provisions → Yes. | H35: Yes
A36: 34 | B36: D3 - Policy Enforcement | C36: n/a (gap) | D36: Cuzzocrea & Belmerabet (2024) | E36: "Organized around seven core topics, Authentication and Authorization, Identity Verification and Risk Management, Attribute Management, Security and Privacy, Audit and Compliance, User Lifecycle Management, and Interoperability and Federation, this study provides "this study provides a detailed examination of these aspects particularly to achieve robust security, privacy, and interoperability across multi- loud platforms." (p.6223) survey scope is IAM taxonomy; policy enforcement not addressed as a distinct governance mechanism in any of the seven topic areas. | F36: 6223 | G36: No policy enforcement content → No. | H36: No
A37: 35 | B37: D3 - Policy Enforcement | C37: D3.4 | D37: Diningrat et al. (2025) | E37: "most of the multi-cloud security issue trends fall into the areas of data, cryptography, authentication and authorization" (p.70006); "authentication and authorization" identified as dominant challenge category across reviewed papers (p.70012). | F37: 70006 | G37: Policy enforcement challenges documented through literature synthesis; no enforcement mechanism defined → Partial. | H37: Partial
A38: 36 | B38: D3 - Policy Enforcement | C38: D3.4 | D38: Hegde et al. (2023) | E38: policy enforcement coverage inferred from overall CCM control coverage percentages (p.4-5); "CCM v4 encapsulates a holistic approach to risk management" (p.5) but Hegde does not isolate policy enforcement as an independent result. | F38: 4-5 | G38: Policy enforcement addressed indirectly through CCM coverage mapping; no standalone enforcement mechanism defined → Partial. | H38: Partial
A39: 37 | B39: D3 - Policy Enforcement | C39: D3.1 | D39: ISO/IEC 27001:2022 | E39: Annex A control "A.5.23 Information security for use of cloud services" (p.12); "A.8.9 configuration management" (p. 16); Clause "5.2 policy (p.3). | F39: 12 | G39: Specific enforceable policy controls defined at clause and Annex A control level → Yes. | H39: Yes
A40: 38 | B40: D3 - Policy Enforcement | C40: n/a (gap) | D40: Kaur et al. (2024) | E40: "The primary goal of this investigation is to create a safe architecture for inter-server communication within multi-cloud systems" (Introduction); paper output is a performance comparison of authentication algorithms - "The achieved response time is 3.85 in SSCA and 2.01 in SIDH" (Results). | F40: 2 | G40: Paper contributes a cryptographic performance benchmark, not a policy enforcement mechanism; no cloud policy definition, enforcement control, or compliance procedure is addressed → No. | H40: No
...

Sheet Coverage Matrix
A1: COVERAGE MATRIX (secondary) - study-level Yes/Partial/No per Table 3.5; identical to thesis Table 4.2 context. Primary coding = sheets 2-4.
A3: Source | B3: Study Type | C3: Layer | D3: D1 | E3: D2 | F3: D3 | G3: D4 | H3: D5 | I3: D6
A4: Yeboah-Ofori et al. (2024) | B4: Empirical study | C4: L2 | D4: Yes | E4: Yes | F4: Partial | G4: Partial | H4: Partial | I4: No
A5: Hegde et al. (2023) | B5: Comparative analysis | C5: L3 | D5: No | E5: Yes | F5: Partial | G5: Partial | H5: Partial | I5: Partial
A6: Diningrat et al. (2025) | B6: Systematic review | C6: L3 | D6: Yes | E6: Partial | F6: Partial | G6: Partial | H6: Yes | I6: No
A7: Aljarrah et al. (2024) | B7: Comparative mapping | C7: L3 | D7: No | E7: Yes | F7: Partial | G7: No | H7: Partial | I7: No
A8: Cuzzocrea & Belmerabet (2024) | B8: Survey | C8: L3 | D8: Yes | E8: Partial | F8: No | G8: No | H8: No | I8: Yes
A9: Kaur et al. (2024) | B9: Empirical study | C9: L2 | D9: Yes | E9: No | F9: No | G9: No | H9: Yes | I9: Yes
A10: Alouffi et al. (2021) | B10: Systematic review | C10: L3 | D10: Partial | E10: No | F10: Partial | G10: No | H10: Partial | I10: No
A11: Ali et al. (2025) | B11: Comprehensive review | C11: L3 | D11: Yes | E11: Yes | F11: Partial | G11: Partial | H11: Partial | I11: Partial
A12: AlGhamdi et al. (2020) | B12: Systematic review | C12: L3 | D12: No | E12: Yes | F12: Partial | G12: No | H12: Partial | I12: No
A13: Pöhn & Hillmann (2021) | B13: Reference model | C13: L3 | D13: No | E13: Partial | F13: No | G13: No | H13: No | I13: Yes
A14: ISO/IEC 27001:2022 | B14: Normative standard | C14: L1 | D14: No | E14: Yes | F14: Yes | G14: Yes | H14: Partial | I14: Partial
... A17: NIST SP 800-210 (Hu et al., 2020) | B17: Normative supplement (Government technical standard, NIST SP) | C17: L1 | D17: No | E17: Partial | F17: Yes | G17: No | H17: Partial | I17: Partial

Sheet Frequency & Themes
A1: CODE FREQUENCY (live) & THEME MAPPING
A2: Code | B2: Code name | C2: # Segments
A3: D1.1 | B3: Single-cloud / architecture-agnostic | C3: =COUNTIF('Coding Book - Detail'!C:C,A3) -> 7
A4: D1.2 | B4: Hybrid-cloud | C4: =COUNTIF('Coding Book - Detail'!C:C,A4) -> 0
A5: D1.3 | B5: Multi-cloud - conceptual / review scope | C5: =COUNTIF('Coding Book - Detail'!C:C,A5) -> 5
A6: D1.4 | B6: Multi-cloud - operational (2+ concurrent providers) | C6: =COUNTIF('Coding Book - Detail'!C:C,A6) -> 2
A7: D2.OC | B7: GV.OC Organizational Context | C7: =COUNTIF('Coding Book - Detail'!C:C,A7) -> 0
A8: D2.RM | B8: GV.RM Risk Mgmt Strategy | C8: =COUNTIF('Coding Book - Detail'!C:C,A8) -> 0
A9: D2.RR | B9: GV.RR Roles, Responsibilities & Authorities | C9: =COUNTIF('Coding Book - Detail'!C:C,A9) -> 0
A10: D2.PO | B10: GV.PO Policy (policy instrument) | C10: =COUNTIF('Coding Book - Detail'!C:C,A10) -> 1
A11: D2.OV | B11: GV.OV Oversight | C11: =COUNTIF('Coding Book - Detail'!C:C,A11) -> 0
A12: D2.SC | B12: GV.SC Supply-Chain / Provider Relationships | C12: =COUNTIF('Coding Book - Detail'!C:C,A12) -> 0
A13: D2.FW | B13: Holistic / whole-framework governance (ISMS-level) | C13: =COUNTIF('Coding Book - Detail'!C:C,A13) -> 7
A14: D2.X | B14: Governance referenced / challenge documented, no framework | C14: =COUNTIF('Coding Book - Detail'!C:C,A14) -> 4
... A35: n/a (gap) | B35: Dimension not substantively addressed | C35: =COUNTIF('Coding Book - Detail'!C:C,A35) -> 19
A37: From codes to themes - Governance Gap Taxonomy (thesis Table 4.5) thin codes are D1.1 (single-cloud only), D3.4 (policy talk, no tool), D4.4 (responsibility mentioned, never allocated), D5.X, D2.X.
A38: Theme | B38: Dimension | C38: Code pattern that constitutes the gap
A39: AAG - Architecture Agnosticism | B39: D1 | C39: D1.1 dominates the frameworks (all three code D1.1/D1.3, never D1.4); operational multi-cloud (D1.4) confined to two empirical studies. | D39: if a framework doesn't know multi-cloud exists (D1), then its governance (D2), enforcement (D3), everything else is automatically blind to it too.
A40: CPCG - Cross-Provider Policy Coordination | B40: D3 | C40: D3.4 (policy specification only) recurs corpus-wide; D3.1 preventive controls appear only inside single providers - no D3.1 at cross-provider level. | D40: D3.4 seven times — your most frequent thin code. The three Yes ratings (ISO, NIST, Hu) all sit in single-provider or architecture-agnostic context. Convergence → gap → CPCG-1, "no policy synchronisation across providers." while reading the D3 evidence, two segments describe a different, second absence: Diningrat (p. 70006) and Ali (p. 11) both describe meaning changing when one policy is translated into AWS SCPs vs Azure Policies vs GCP bindings. That is not "no synchronisation" — that is semantic drift, a structurally separate problem → it earns its own row, CPCG-2, with exactly those two sources in the Evidence column.
A41: SRBG - Shared Responsibility Boundary | B41: D4 | C41: D4.4 (referenced, not allocated) dominates the literature; D4.3 allocations exist only inside single-provider framework models - never reconciled across providers.
A42: CRPNG - Cross-Cloud Risk Posture Normalisation | B42: D5 | C42: D5.DE monitoring exists per provider; no code instance normalises posture across providers - D5.X and per-provider D5.DE constitute the gap.
A43: FIAMG - Federated IAM Governance | B43: D6 | C43: D6.IF exists (CSA, Poehn, Kaur, Cuzzocrea) but as guidance/technique; D6.AA without D6.IF in the frameworks; multiple n/a - no framework mandates cross-provider IdP governance.

Sheet PRISMA Search Log
A1: PRISMA Search Log
A2: Thesis: Comparative Analysis of Cybersecurity Governance Frameworks for Multi-Cloud Environments
A4: Database | B4: Search Date | C4: Records Retrieved | D4: After Deduplication
A5: IEEE Xplore | B5: April 2026 | C5: 45 | D5: 45
A6: ACM Digital Library | B6: April 2026 | C6: 134 | D6: 134
A7: SpringerLink | B7: April 2026 | C7: 423 | D7: 423
A8: ScienceDirect (Elsevier) | B8: April 2026 | C8: 217 | D8: 217
A9: EBSCO HOST | B9: April 2026 | C9: 996 | D9: 777
A10: Citation Tracking | B10: April 2026 | C10: 3 | D10: 3
A11: Total | B11: - | C11: =SUM(C5:C10) -> 1818 | D11: =SUM(D5:D10) -> 1599 | E11: Difference : 219
A12: Evidence of how many results each database gave me.
A13: HOW TO READ: Records Retrieved = raw hits from each database search. After Deduplication = unique records remaining. EBSCO HOST figure (777) is confirmed by EBSCO's own system message: 'A total of 777 unique records were presented after deduplication.' All other databases showed no overlap with previously searched databases. Total unique records entering title/abstract screening: 1,599.

Sheet PRISMA Screening Log
A1: PRISMA 2020 Screening Stage Summary
A2: Stage
A3: Total unique records after deduplication | B3: 1599 | C3: Entering title/abstract screening
A4: Excluded at title/abstract stage | B4: 1583 | C4: Off-topic, single-cloud only, non-peer-reviewed, outside 2020–2025, wrong language
A5: Records advancing to full-text review | B5: =B3-B4 -> 16 | C5: Assessed against full inclusion/exclusion criteria (8 from database search + 2 from citation tracking, plus 6 which will be excluded later)
A6: Excluded at full-text stage | B6: 6 | C6: Listed below with specific reasons
A7: Final included corpus | B7: 10 peer-reviewed (8 PRISMA + 2 citation tracking) + 3 normative frameworks + 1 normative supplement (NIST SP) = 14 total
A9: Individual Screening Decisions (Full-Text Reviewed Papers) - PRISMA Screening Log
A10: Title | B10: Author(s) | C10: Year | D10: Decision | E10: Exclusion Reason
A11: Data security and governance in multi-cloud computing environment | B11: Yeboah-Ofori et al. | C11: 2024 | D11: Include | E11: -
A12: Cloud security frameworks: A comparison to evaluate cloud control standards | B12: Hegde et al. | C12: 2023 | D12: Include | E12: -
A13: Security issues in multi-cloud: A systematic literature review | B13: Diningrat et al. | C13: 2025 | D13: Include | E13: -
A14: On the comparative analysis of trends in cybersecurity risk assessment, governance, and compliance frameworks | B14: Aljarrah et al. | C14: 2024 | D14: Include | E14: -
A15: Privacy-preserving identity and access management in multiple cloud environments: Models, issues, and solutions | B15: Cuzzocrea & Belmerabet | C15: 2024 | D15: Include | E15: -
A16: Multi-cloud security model: Establishment of inter-server communication for authentication integrity | B16: Kaur et al. | C16: 2024 | D16: Include | E16: -
A17: A systematic literature review on cloud computing security: Threats and mitigation strategies | B17: Alouffi et al. | C17: 2021 | D17: Include | E17: -
A18: Security and privacy in multi-cloud and hybrid cloud environments | B18: Ali et al. | C18: 2025 | D18: Include | E18: -
A19: ISO/IEC 27001:2022 - Information security management systems | B19: ISO/IEC | C19: 2022 | D19: Include | E19: - (normative framework)
A20: NIST Cybersecurity Framework 2.0 | B20: NIST | C20: 2024 | D20: Include | E20: - (normative framework)
A21: CSA Security Guidance v5 | B21: CSA | C21: 2021 | D21: Include | E21: - (normative framework)
A22: General access control guidance for cloud systems (NIST SP 800-210) | B22: Hu et al. | C22: 2020 | D22: Include | E22: - (normative supplement / government technical standard)
A23: Information security governance challenges and critical success factors: Systematic review | B23: AlGhamdi et al. | C23: 2020 | D23: Include | E23: - (citation tracking)
A24: Reference service model for federated identity management | B24: Pöhn & Hillmann | C24: 2021 | D24: Include | E24: - (citation tracking)
A25: Systemic Risk and Vulnerability Analysis of Multi-cloud Environments | B25: Reece et al. | C25: 2023 | D25: Exclude | E25: Not peer-reviewed
A26: A survey on security challenges in cloud computing: issues, threats, and solutions | B26: Tabrizchi & Kuchaki Rafsanjani | C26: 2020 | D26: Exclude | E26: Single-cloud focus only - no multi-cloud governance framework analysis
A27: Blockchain-based trust management in cloud computing systems: a taxonomy, review and future directions | B27: Li et al. | C27: 2021 | D27: Exclude | E27: Blockchain trust management focus - no cybersecurity governance framework analysis
A28: Cloud Incident Response: a Comprehensive Analysis | B28: Brumă | C28: 2023 | D28: Exclude | E28: Incident response focus - outside governance framework scope
A29: A review on cloud security issues and solutions | B29: Chaudhari et al. | C29: 2023 | D29: Exclude | E29: General cloud security survey - no governance framework or multi-cloud analysis
A30: Cloud-Based Business Process Security Risk Management: a systematic review | B30: Abioye et al. | C30: 2021 | D30: Exclude | E30: Business process risk management focus - not a multi-cloud governance framework comparison
